<?xml version="1.0" ?>
<!-- =================================================================================== -->
<!-- |    This document was autogenerated by xacro from yumi_camera_scene.xacro        | -->
<!-- |    EDITING THIS FILE BY HAND IS NOT RECOMMENDED                                 | -->
<!-- =================================================================================== -->
<robot name="Robot1" xmlns:xacro="http://ros.org/wiki/xacro">
  <link name="yumi_body"/>
  <link name="target_frame">
    <visual>
      <origin xyz="0.19 0.035 0.0"/>
      <geometry>
        <box size="0.53 0.205 0.005"/>
      </geometry>
    </visual>
  </link>
  <joint name="$world_2_cal_target_joint" type="fixed">
    <parent link="yumi_body"/>
    <child link="target_frame"/>
    <origin rpy="0 0 0" xyz="0.3 0 0.025"/>
  </joint>
  <link name="kinect2_link">
    <visual>
      <origin xyz=".125 .035 .0"/>
      <geometry>
        <box size=".25 .07 .045"/>
      </geometry>
    </visual>
  </link>
  <link name="kinect2_link_x_trans">
    <visual>
      <origin rpy="0 0 0" xyz="0 0 0"/>
      <geometry>
        <sphere radius="0.0005"/>
      </geometry>
    </visual>
  </link>
  <link name="kinect2_link_y_trans"/>
  <link name="kinect2_link_z_trans"/>
  <link name="kinect2_link_pitch"/>
  <link name="kinect2_link_yaw"/>
  <joint name="kinect2_link_x_joint" type="prismatic">
    <parent link="yumi_body"/>
    <child link="kinect2_link_x_trans"/>
    <origin rpy="0 0 0" xyz="0 0 0"/>
    <axis rpy="0 0 0" xyz="1 0 0"/>
    <limit effort="30" lower="-1.0" upper="1.0" velocity="0.0508"/>
  </joint>
  <joint name="kinect2_link_y_joint" type="prismatic">
    <parent link="kinect2_link_x_trans"/>
    <child link="kinect2_link_y_trans"/>
    <origin rpy="0 0 0" xyz="0 0 0"/>
    <axis rpy="0 0 0" xyz="0 1 0"/>
    <limit effort="30" lower="-1.0" upper="1.0" velocity="0.0508"/>
  </joint>
  <joint name="kinect2_link_z_joint" type="prismatic">
    <parent link="kinect2_link_y_trans"/>
    <child link="kinect2_link_z_trans"/>
    <origin rpy="0 0 0" xyz="0 0 0"/>
    <axis rpy="0 0 0" xyz="0 0 1"/>
    <limit effort="30" lower="-1.0" upper="1.0" velocity="0.0508"/>
  </joint>
  <joint name="kinect2_link_yaw_joint" type="revolute">
    <parent link="kinect2_link_z_trans"/>
    <child link="kinect2_link_yaw"/>
    <origin rpy="0 0 0" xyz="0 0 0"/>
    <limit effort="2" lower="-6.2832" upper="6.2832" velocity="10"/>
    <axis xyz="0 0 1"/>
  </joint>
  <joint name="kinect2_link_pitch_joint" type="revolute">
    <parent link="kinect2_link_yaw"/>
    <child link="kinect2_link_pitch"/>
    <origin rpy="0 0 0" xyz="0 0 0"/>
    <limit effort="2" lower="-6.2832" upper="6.2832" velocity="10"/>
    <axis xyz="0 1 0"/>
  </joint>
  <joint name="kinect2_link_roll_joint" type="revolute">
    <parent link="kinect2_link_pitch"/>
    <child link="kinect2_link"/>
    <origin rpy="0 0 0" xyz="0 0 0"/>
    <limit effort="2" lower="-6.2832" upper="6.2832" velocity="10"/>
    <axis xyz="1 0 0"/>
  </joint>
  <material name="cameradark_silver">
    <color rgba="0.15 0.15 0.15 1"/>
  </material>
  <!-- sensor links -->
  <link name="camera_link"/>
  <link name="camera_frame">
    <visual>
      <origin rpy="0 0 0" xyz="0 0 0"/>
      <geometry>
        <box size="0.04 0.22 0.04"/>
      </geometry>
      <material name="cameradark_silver"/>
    </visual>
    <collision>
      <origin rpy="0 0 0" xyz="0 0 0"/>
      <geometry>
        <box size="0.04 0.22 0.04"/>
      </geometry>
    </collision>
  </link>
  <link name="camera_depth_link">
    <visual>
      <origin rpy="0 0 0" xyz="0 0 0"/>
      <geometry>
        <sphere radius="0.0005"/>
      </geometry>
    </visual>
  </link>
  <link name="camera_rgb_link">
    <visual>
      <origin rpy="0 0 0" xyz="0 0 0"/>
      <geometry>
        <sphere radius="0.0005"/>
      </geometry>
    </visual>
  </link>
  <link name="camera_rgb_frame"/>
  <link name="camera_depth_optical_frame"/>
  <link name="camera_rgb_optical_frame"/>
  <!-- end of sensor links -->
  <link name="camera_link_x_trans">
    <visual>
      <origin rpy="0 0 0" xyz="0 0 0"/>
      <geometry>
        <sphere radius="0.0005"/>
      </geometry>
    </visual>
  </link>
  <link name="camera_link_y_trans"/>
  <link name="camera_link_z_trans"/>
  <link name="camera_link_pitch"/>
  <link name="camera_link_yaw"/>
  <joint name="camera_link_x_joint" type="prismatic">
    <parent link="yumi_body"/>
    <child link="camera_link_x_trans"/>
    <origin rpy="0 0 0" xyz="0 0 0"/>
    <axis rpy="0 0 0" xyz="1 0 0"/>
    <limit effort="30" lower="-1.0" upper="1.0" velocity="0.0508"/>
  </joint>
  <joint name="camera_link_y_joint" type="prismatic">
    <parent link="camera_link_x_trans"/>
    <child link="camera_link_y_trans"/>
    <origin rpy="0 0 0" xyz="0 0 0"/>
    <axis rpy="0 0 0" xyz="0 1 0"/>
    <limit effort="30" lower="-1.0" upper="1.0" velocity="0.0508"/>
  </joint>
  <joint name="camera_link_z_joint" type="prismatic">
    <parent link="camera_link_y_trans"/>
    <child link="camera_link_z_trans"/>
    <origin rpy="0 0 0" xyz="0 0 0"/>
    <axis rpy="0 0 0" xyz="0 0 1"/>
    <limit effort="30" lower="-1.0" upper="1.0" velocity="0.0508"/>
  </joint>
  <joint name="camera_link_yaw_joint" type="revolute">
    <parent link="camera_link_z_trans"/>
    <child link="camera_link_yaw"/>
    <origin rpy="0 0 0" xyz="0 0 0"/>
    <limit effort="2" lower="-6.2832" upper="6.2832" velocity="10"/>
    <axis xyz="0 0 1"/>
  </joint>
  <joint name="camera_link_pitch_joint" type="revolute">
    <parent link="camera_link_yaw"/>
    <child link="camera_link_pitch"/>
    <origin rpy="0 0 0" xyz="0 0 0"/>
    <limit effort="2" lower="-6.2832" upper="6.2832" velocity="10"/>
    <axis xyz="0 1 0"/>
  </joint>
  <joint name="camera_link_roll_joint" type="revolute">
    <parent link="camera_link_pitch"/>
    <child link="camera_link"/>
    <origin rpy="0 0 0" xyz="0 0 0"/>
    <limit effort="2" lower="-6.2832" upper="6.2832" velocity="10"/>
    <axis xyz="1 0 0"/>
  </joint>
  <!-- sensor joints -->
  <joint name="camera_frame_joint" type="fixed">
    <parent link="camera_link"/>
    <child link="camera_frame"/>
    <origin rpy="0 0 0" xyz="0 0 0"/>
  </joint>
  <joint name="camera_depth_joint" type="fixed">
    <parent link="camera_frame"/>
    <child link="camera_depth_link"/>
    <origin rpy="0 0 0" xyz="0 0 0"/>
  </joint>
  <joint name="camera_depth_optical_frame_joint" type="fixed">
    <parent link="camera_depth_link"/>
    <child link="camera_depth_optical_frame"/>
    <origin rpy="-1.57 0 -1.57" xyz="0 0 0"/>
  </joint>
  <joint name="camera_rgb_joint" type="fixed">
    <parent link="camera_depth_link"/>
    <child link="camera_rgb_link"/>
    <origin rpy="0 0 0" xyz="0 -0.03 0"/>
  </joint>
  <joint name="camera_rgb_frame_joint" type="fixed">
    <parent link="camera_rgb_optical_frame"/>
    <child link="camera_rgb_frame"/>
    <origin rpy="0 0 0" xyz="0 0.0 0"/>
  </joint>
  <joint name="camera_rgb_optical_frame_joint" type="fixed">
    <parent link="camera_rgb_link"/>
    <child link="camera_rgb_optical_frame"/>
    <origin rpy="-1.57 0 -1.57" xyz="0 0 0"/>
  </joint>
  <!-- end of sensor joints -->
</robot>

